ERROR    my_log:common_fun.py:273 等待元素可点击交易失败
ERROR    my_log:common_fun.py:274 Message: 
Traceback (most recent call last):
  File "D:\xiaxy\automation_test2022.4.22\common\common_fun.py", line 270, in get_clickable_element
    ele = WebDriverWait(self.driver,timeout,0.5).until(EC.element_to_be_clickable(loc))
  File "D:\xiaxy\python\lib\site-packages\selenium\webdriver\support\wait.py", line 80, in until
    raise TimeoutException(message, screen, stacktrace)
selenium.common.exceptions.TimeoutException: Message: 

INFO     my_log:common_fun.py:260 对【交易】---操作成功进行截图成功
ERROR    my_log:common_fun.py:273 等待元素可点击返回失败
ERROR    my_log:common_fun.py:274 Message: An unknown server-side error occurred while processing the command. Original error: 'POST /element' cannot be proxied to UiAutomator2 server because the instrumentation process is not running (probably crashed). Check the server log and/or the logcat output for more details
Traceback (most recent call last):
  File "D:\xiaxy\automation_test2022.4.22\common\common_fun.py", line 270, in get_clickable_element
    ele = WebDriverWait(self.driver,timeout,0.5).until(EC.element_to_be_clickable(loc))
  File "D:\xiaxy\python\lib\site-packages\selenium\webdriver\support\wait.py", line 71, in until
    value = method(self._driver)
  File "D:\xiaxy\python\lib\site-packages\selenium\webdriver\support\expected_conditions.py", line 297, in __call__
    element = visibility_of_element_located(self.locator)(driver)
  File "D:\xiaxy\python\lib\site-packages\selenium\webdriver\support\expected_conditions.py", line 128, in __call__
    return _element_if_visible(_find_element(driver, self.locator))
  File "D:\xiaxy\python\lib\site-packages\selenium\webdriver\support\expected_conditions.py", line 415, in _find_element
    raise e
  File "D:\xiaxy\python\lib\site-packages\selenium\webdriver\support\expected_conditions.py", line 411, in _find_element
    return driver.find_element(*by)
  File "D:\xiaxy\python\lib\site-packages\appium\webdriver\webdriver.py", line 283, in find_element
    return self.execute(RemoteCommand.FIND_ELEMENT, {'using': by, 'value': value})['value']
  File "D:\xiaxy\python\lib\site-packages\selenium\webdriver\remote\webdriver.py", line 321, in execute
    self.error_handler.check_response(response)
  File "D:\xiaxy\python\lib\site-packages\appium\webdriver\errorhandler.py", line 31, in check_response
    raise wde
  File "D:\xiaxy\python\lib\site-packages\appium\webdriver\errorhandler.py", line 26, in check_response
    super().check_response(response)
  File "D:\xiaxy\python\lib\site-packages\selenium\webdriver\remote\errorhandler.py", line 242, in check_response
    raise exception_class(message, screen, stacktrace)
selenium.common.exceptions.WebDriverException: Message: An unknown server-side error occurred while processing the command. Original error: 'POST /element' cannot be proxied to UiAutomator2 server because the instrumentation process is not running (probably crashed). Check the server log and/or the logcat output for more details

ERROR    my_log:common_fun.py:256 对【返回】---操作失败进行截图失败
ERROR    my_log:common_fun.py:257 Message: An unknown server-side error occurred while processing the command. Original error: 'GET /screenshot' cannot be proxied to UiAutomator2 server because the instrumentation process is not running (probably crashed). Check the server log and/or the logcat output for more details
Traceback (most recent call last):
  File "D:\xiaxy\automation_test2022.4.22\common\common_fun.py", line 270, in get_clickable_element
    ele = WebDriverWait(self.driver,timeout,0.5).until(EC.element_to_be_clickable(loc))
  File "D:\xiaxy\python\lib\site-packages\selenium\webdriver\support\wait.py", line 71, in until
    value = method(self._driver)
  File "D:\xiaxy\python\lib\site-packages\selenium\webdriver\support\expected_conditions.py", line 297, in __call__
    element = visibility_of_element_located(self.locator)(driver)
  File "D:\xiaxy\python\lib\site-packages\selenium\webdriver\support\expected_conditions.py", line 128, in __call__
    return _element_if_visible(_find_element(driver, self.locator))
  File "D:\xiaxy\python\lib\site-packages\selenium\webdriver\support\expected_conditions.py", line 415, in _find_element
    raise e
  File "D:\xiaxy\python\lib\site-packages\selenium\webdriver\support\expected_conditions.py", line 411, in _find_element
    return driver.find_element(*by)
  File "D:\xiaxy\python\lib\site-packages\appium\webdriver\webdriver.py", line 283, in find_element
    return self.execute(RemoteCommand.FIND_ELEMENT, {'using': by, 'value': value})['value']
  File "D:\xiaxy\python\lib\site-packages\selenium\webdriver\remote\webdriver.py", line 321, in execute
    self.error_handler.check_response(response)
  File "D:\xiaxy\python\lib\site-packages\appium\webdriver\errorhandler.py", line 31, in check_response
    raise wde
  File "D:\xiaxy\python\lib\site-packages\appium\webdriver\errorhandler.py", line 26, in check_response
    super().check_response(response)
  File "D:\xiaxy\python\lib\site-packages\selenium\webdriver\remote\errorhandler.py", line 242, in check_response
    raise exception_class(message, screen, stacktrace)
selenium.common.exceptions.WebDriverException: Message: An unknown server-side error occurred while processing the command. Original error: 'POST /element' cannot be proxied to UiAutomator2 server because the instrumentation process is not running (probably crashed). Check the server log and/or the logcat output for more details


During handling of the above exception, another exception occurred:

Traceback (most recent call last):
  File "D:\xiaxy\automation_test2022.4.22\common\common_fun.py", line 254, in error_save_screenshot
    self.driver.save_screenshot(file_path)
  File "D:\xiaxy\python\lib\site-packages\selenium\webdriver\remote\webdriver.py", line 1055, in save_screenshot
    return self.get_screenshot_as_file(filename)
  File "D:\xiaxy\python\lib\site-packages\selenium\webdriver\remote\webdriver.py", line 1032, in get_screenshot_as_file
    png = self.get_screenshot_as_png()
  File "D:\xiaxy\python\lib\site-packages\selenium\webdriver\remote\webdriver.py", line 1064, in get_screenshot_as_png
    return base64.b64decode(self.get_screenshot_as_base64().encode('ascii'))
  File "D:\xiaxy\python\lib\site-packages\selenium\webdriver\remote\webdriver.py", line 1074, in get_screenshot_as_base64
    return self.execute(Command.SCREENSHOT)['value']
  File "D:\xiaxy\python\lib\site-packages\selenium\webdriver\remote\webdriver.py", line 321, in execute
    self.error_handler.check_response(response)
  File "D:\xiaxy\python\lib\site-packages\appium\webdriver\errorhandler.py", line 31, in check_response
    raise wde
  File "D:\xiaxy\python\lib\site-packages\appium\webdriver\errorhandler.py", line 26, in check_response
    super().check_response(response)
  File "D:\xiaxy\python\lib\site-packages\selenium\webdriver\remote\errorhandler.py", line 242, in check_response
    raise exception_class(message, screen, stacktrace)
selenium.common.exceptions.WebDriverException: Message: An unknown server-side error occurred while processing the command. Original error: 'GET /screenshot' cannot be proxied to UiAutomator2 server because the instrumentation process is not running (probably crashed). Check the server log and/or the logcat output for more details