{"uuid": "a8a494f0-5714-4cde-bf6a-828143a937ce", "children": ["b222a22c-dd1a-44a6-8931-dcb267268c6f", "947a1842-78de-453b-b4b2-8aeefc0a5bcc", "1012226d-f68c-4294-9331-3b080831d996", "2dd1ca06-cb48-4a90-b0dd-f6094e4742c8", "fc6edef4-17c3-4577-b6fb-d4c06686cdc9", "ca3daa7b-55e6-4237-a2f6-482287c95112", "d850526d-cc24-4c4a-a0b4-8c516e635c13", "535aedf0-2b21-4812-9b13-3fff1b35cfe4", "2ca5dfad-6320-4050-a94d-96fc2b618003", "8792cfd5-f858-46cb-96be-c600f1638090", "bd474da6-c498-4d69-9a95-32abd297ffd2", "08a82467-100e-4dde-aa5a-4cfc9e502747", "785f4e9c-348c-4255-a008-3bb22954d111", "7b1ad193-8ab6-4ba7-8207-a9c6ac4a158a", "e0a329ee-18d6-41a3-88fd-0ef48c095729", "93ca7486-aad0-444f-b2d6-cb8401d01658", "853c15a4-75a3-4fd9-882f-e105fe4c4d08", "2e1ebd0c-d15e-4dc5-91ef-bbcbfbace8fb", "bd170340-46b2-4db9-a9cc-ead9930413d1", "ae25b1f8-a3f6-46ba-804f-c8617aedf57d", "a40d80bb-b19d-4416-8cbb-931071fbb40a", "87a54ae1-826e-4502-a452-3057de11547a", "5b48a9f8-0635-448a-9161-be22b89f9458", "7a0075b6-e543-4f80-9ac1-03db29d169a5", "ac7742f9-3936-4058-8d16-f3d039f7bd9f", "cf29aad4-0933-4cf8-84ba-4ce5492a4369", "85853171-afa4-4739-99e2-27c9c4865221", "2b49e2c0-2395-4c89-a214-fb53266b6844", "f41a7989-9522-4618-bc8b-75e3f9f00770", "b366d824-9b95-4cac-b72e-916e970d1be4", "e1a55e20-d669-4683-b84e-babf658d32fd", "aaaf6cb4-cd00-42af-8756-62208ada4bdb", "52eff2bf-9b83-4a72-ab16-4649103efb61", "89f24048-a0e1-47fb-91a5-2aa796992a8d", "877ac80b-90f0-432b-b559-b7e29d7ac015", "f686a757-6d74-4eb6-9b20-9542ccb28837", "cd2ea770-8209-4a3e-a3d1-6f096d44105a", "f9e50b4c-db78-4286-9e8a-d2984f329fe1", "24f03357-a387-44c5-b1d6-80513e31929f", "c67d8cf8-c9d0-4f77-8343-245cf05d5cf6", "6ebfa181-9690-4a01-a63f-293c7b42ac4d", "41b6f846-d4c9-444b-9f3a-73c044f43c8f", "80c80fd7-bd24-4f68-ac1a-b435590bef80"], "befores": [{"name": "back_fixture", "status": "passed", "start": 1652713065250, "stop": 1652713065250}], "afters": [{"name": "back_fixture::0", "status": "broken", "statusDetails": {"message": "selenium.common.exceptions.WebDriverException: Message: An unknown server-side error occurred while processing the command. Original error: 'GET /screenshot' cannot be proxied to UiAutomator2 server because the instrumentation process is not running (probably crashed). Check the server log and/or the logcat output for more details\n\n", "trace": "  File \"D:\\xiaxy\\python\\lib\\site-packages\\allure_commons\\_allure.py\", line 200, in __call__\n    return self._fixture_function(*args, **kwargs)\n  File \"D:\\xiaxy\\python\\lib\\site-packages\\_pytest\\fixtures.py\", line 941, in _teardown_yield_fixture\n    next(it)\n  File \"D:\\xiaxy\\automation_test2022.4.22\\testcases\\conftest.py\", line 74, in back_fixture\n    com.back()\n  File \"D:\\xiaxy\\automation_test2022.4.22\\common\\common_fun.py\", line 367, in back\n    self.get_clickable_element(self.Back,\"返回\")\n  File \"D:\\xiaxy\\automation_test2022.4.22\\common\\common_fun.py\", line 275, in get_clickable_element\n    self.error_save_screenshot(desc)\n  File \"D:\\xiaxy\\automation_test2022.4.22\\common\\common_fun.py\", line 258, in error_save_screenshot\n    raise e\n  File \"D:\\xiaxy\\automation_test2022.4.22\\common\\common_fun.py\", line 254, in error_save_screenshot\n    self.driver.save_screenshot(file_path)\n  File \"D:\\xiaxy\\python\\lib\\site-packages\\selenium\\webdriver\\remote\\webdriver.py\", line 1055, in save_screenshot\n    return self.get_screenshot_as_file(filename)\n  File \"D:\\xiaxy\\python\\lib\\site-packages\\selenium\\webdriver\\remote\\webdriver.py\", line 1032, in get_screenshot_as_file\n    png = self.get_screenshot_as_png()\n  File \"D:\\xiaxy\\python\\lib\\site-packages\\selenium\\webdriver\\remote\\webdriver.py\", line 1064, in get_screenshot_as_png\n    return base64.b64decode(self.get_screenshot_as_base64().encode('ascii'))\n  File \"D:\\xiaxy\\python\\lib\\site-packages\\selenium\\webdriver\\remote\\webdriver.py\", line 1074, in get_screenshot_as_base64\n    return self.execute(Command.SCREENSHOT)['value']\n  File \"D:\\xiaxy\\python\\lib\\site-packages\\selenium\\webdriver\\remote\\webdriver.py\", line 321, in execute\n    self.error_handler.check_response(response)\n  File \"D:\\xiaxy\\python\\lib\\site-packages\\appium\\webdriver\\errorhandler.py\", line 31, in check_response\n    raise wde\n  File \"D:\\xiaxy\\python\\lib\\site-packages\\appium\\webdriver\\errorhandler.py\", line 26, in check_response\n    super().check_response(response)\n  File \"D:\\xiaxy\\python\\lib\\site-packages\\selenium\\webdriver\\remote\\errorhandler.py\", line 242, in check_response\n    raise exception_class(message, screen, stacktrace)\n"}, "start": 1652713065368, "stop": 1652713065377}], "start": 1652713065250, "stop": 1652713065377}