{
  "uid" : "a6e93de61bed7dc3",
  "name" : "test_buy_zt",
  "fullName" : "testGp.test_new_Gp.TestGp#test_buy_zt",
  "historyId" : "1f23c40b48eebe1f0a699f290b0a2e32",
  "time" : {
    "start" : 1652795333978,
    "stop" : 1652795333978,
    "duration" : 0
  },
  "status" : "broken",
  "statusMessage" : "AttributeError: 'Login' object has no attribute 'gp_login'",
  "statusTrace" : "driver_fixture = <appium.webdriver.webdriver.WebDriver (session=\"0e7b83d5-90bd-4243-ba0f-6351e0c81c1e\")>\n\n    @pytest.fixture(scope='session',autouse=False)\n    def gp_login_fixture(driver_fixture):\n        csv_file=BASE_DIR + '\\datas\\login.csv'\n        print(\"csv_file:%s\"%csv_file)\n        driver=driver_fixture\n        com=Common(driver)\n        data=com.get_csv_data(csv_file,2)\n        time.sleep(2)\n        trd=First(driver)\n        trd.to_login()\n        logn=Login(driver)\n>       logn.gp_login(data[0],data[1])\nE       AttributeError: 'Login' object has no attribute 'gp_login'\n\nconftest.py:54: AttributeError",
  "flaky" : false,
  "newFailed" : false,
  "beforeStages" : [ {
    "name" : "driver_fixture",
    "time" : {
      "start" : 1652794360868,
      "stop" : 1652794396581,
      "duration" : 35713
    },
    "status" : "passed",
    "steps" : [ ],
    "attachments" : [ ],
    "parameters" : [ ],
    "stepsCount" : 0,
    "hasContent" : false,
    "shouldDisplayMessage" : false,
    "attachmentsCount" : 0
  }, {
    "name" : "login_fixture",
    "time" : {
      "start" : 1652794396581,
      "stop" : 1652794501486,
      "duration" : 104905
    },
    "status" : "passed",
    "steps" : [ ],
    "attachments" : [ ],
    "parameters" : [ ],
    "stepsCount" : 0,
    "hasContent" : false,
    "shouldDisplayMessage" : false,
    "attachmentsCount" : 0
  }, {
    "name" : "gp_login_fixture",
    "time" : {
      "start" : 1652795328232,
      "stop" : 1652795333892,
      "duration" : 5660
    },
    "status" : "broken",
    "statusMessage" : "AttributeError: 'Login' object has no attribute 'gp_login'\n",
    "statusTrace" : "  File \"D:\\xiaxy\\python\\lib\\site-packages\\pluggy\\callers.py\", line 187, in _multicall\n    res = hook_impl.function(*args)\n  File \"D:\\xiaxy\\python\\lib\\site-packages\\_pytest\\fixtures.py\", line 1126, in pytest_fixture_setup\n    result = call_fixture_func(fixturefunc, request, kwargs)\n  File \"D:\\xiaxy\\python\\lib\\site-packages\\_pytest\\fixtures.py\", line 932, in call_fixture_func\n    fixture_result = fixturefunc(**kwargs)\n  File \"D:\\xiaxy\\automation_test2022.4.22\\testcases\\conftest.py\", line 54, in gp_login_fixture\n    logn.gp_login(data[0],data[1])\n",
    "steps" : [ ],
    "attachments" : [ ],
    "parameters" : [ ],
    "stepsCount" : 0,
    "hasContent" : true,
    "shouldDisplayMessage" : true,
    "attachmentsCount" : 0
  }, {
    "name" : "back_fixture",
    "time" : {
      "start" : 1652795334309,
      "stop" : 1652795334310,
      "duration" : 1
    },
    "status" : "passed",
    "steps" : [ ],
    "attachments" : [ ],
    "parameters" : [ ],
    "stepsCount" : 0,
    "hasContent" : false,
    "shouldDisplayMessage" : false,
    "attachmentsCount" : 0
  }, {
    "name" : "old_pwd",
    "time" : {
      "start" : 1652794797078,
      "stop" : 1652794797079,
      "duration" : 1
    },
    "status" : "passed",
    "steps" : [ ],
    "attachments" : [ ],
    "parameters" : [ ],
    "stepsCount" : 0,
    "hasContent" : false,
    "shouldDisplayMessage" : false,
    "attachmentsCount" : 0
  } ],
  "afterStages" : [ {
    "name" : "driver_fixture::0",
    "time" : {
      "start" : 1652796124797,
      "stop" : 1652796124797,
      "duration" : 0
    },
    "status" : "passed",
    "steps" : [ ],
    "attachments" : [ ],
    "parameters" : [ ],
    "stepsCount" : 0,
    "hasContent" : false,
    "shouldDisplayMessage" : false,
    "attachmentsCount" : 0
  }, {
    "name" : "back_fixture::0",
    "time" : {
      "start" : 1652795347356,
      "stop" : 1652795347464,
      "duration" : 108
    },
    "status" : "passed",
    "steps" : [ ],
    "attachments" : [ ],
    "parameters" : [ ],
    "stepsCount" : 0,
    "hasContent" : false,
    "shouldDisplayMessage" : false,
    "attachmentsCount" : 0
  }, {
    "name" : "old_pwd::0",
    "time" : {
      "start" : 1652796124790,
      "stop" : 1652796124790,
      "duration" : 0
    },
    "status" : "passed",
    "steps" : [ ],
    "attachments" : [ ],
    "parameters" : [ ],
    "stepsCount" : 0,
    "hasContent" : false,
    "shouldDisplayMessage" : false,
    "attachmentsCount" : 0
  } ],
  "labels" : [ {
    "name" : "tag",
    "value" : "@pytest.mark.usefixtures('back_fixture')"
  }, {
    "name" : "parentSuite",
    "value" : "testGp"
  }, {
    "name" : "suite",
    "value" : "test_new_Gp"
  }, {
    "name" : "subSuite",
    "value" : "TestGp"
  }, {
    "name" : "host",
    "value" : "Win102021AVUCSJ"
  }, {
    "name" : "thread",
    "value" : "10404-MainThread"
  }, {
    "name" : "framework",
    "value" : "pytest"
  }, {
    "name" : "language",
    "value" : "cpython3"
  }, {
    "name" : "package",
    "value" : "testGp.test_new_Gp"
  }, {
    "name" : "resultFormat",
    "value" : "allure2"
  } ],
  "parameters" : [ ],
  "links" : [ ],
  "hidden" : false,
  "retry" : false,
  "extra" : {
    "severity" : "normal",
    "retries" : [ {
      "uid" : "6b001ad313cf0111",
      "status" : "broken",
      "statusDetails" : "selenium.common.exceptions.WebDriverException: Message: An unknown server-side error occurred while processing the command. Original error: 'GET /screenshot' cannot be proxied to UiAutomator2 server because the instrumentation process is not running (probably crashed). Check the server log and/or the logcat output for more details",
      "time" : {
        "start" : 1652713061281,
        "stop" : 1652713061281,
        "duration" : 0
      }
    }, {
      "uid" : "159776a667bc8f2d",
      "status" : "broken",
      "statusDetails" : "selenium.common.exceptions.WebDriverException: Message: An unknown server-side error occurred while processing the command. Original error: 'GET /screenshot' cannot be proxied to UiAutomator2 server because the instrumentation process is not running (probably crashed). Check the server log and/or the logcat output for more details",
      "time" : {
        "start" : 1652712717738,
        "stop" : 1652712717738,
        "duration" : 0
      }
    }, {
      "uid" : "76f8600f9ef3b85e",
      "status" : "broken",
      "statusDetails" : "selenium.common.exceptions.TimeoutException: Message:",
      "time" : {
        "start" : 1652710823308,
        "stop" : 1652710823308,
        "duration" : 0
      }
    }, {
      "uid" : "1700b901d6ae4760",
      "status" : "broken",
      "statusDetails" : "selenium.common.exceptions.TimeoutException: Message:",
      "time" : {
        "start" : 1652710342908,
        "stop" : 1652710342908,
        "duration" : 0
      }
    }, {
      "uid" : "52f6cfe543d6a2c",
      "status" : "broken",
      "statusDetails" : "selenium.common.exceptions.WebDriverException: Message: An unknown server-side error occurred while processing the command. Original error: Could not find a connected Android device in 20093ms.",
      "time" : {
        "start" : 1652710087474,
        "stop" : 1652710087474,
        "duration" : 0
      }
    } ],
    "categories" : [ {
      "name" : "Test defects",
      "matchedStatuses" : [ ],
      "flaky" : false
    } ],
    "tags" : [ "@pytest.mark.usefixtures('back_fixture')" ]
  },
  "source" : "a6e93de61bed7dc3.json",
  "parameterValues" : [ ]
}